Workbook

Sheet Overview
C2: B2B SaaS Paid Media Audit Overview & Score Summary
C5: Weighted score | E5: Max score | G5: Audit maturity | I5: Status | J5: Company
C6: ='SaaS Audit Worksheet'!F71 -> 0 | E6: 238.5 | G6: =IFERROR(C6/E6,"") -> 0 | I6: =IF(G6="","Not scored",IF(G6<0.4,"High risk",IF(G6<0.6,"Operational but limited",IF(G6<0.8,"Strong base","Advanced")))) -> High risk | J6: Website
C7: 1 | D7: Weak / missing | E7: 3 | F7: Functional | G7: 5 | H7: Advanced / scalable | J7: Auditor
C8: Use this scorecard to evaluate whether a SaaS paid media program is built for qualified pipeline and scalable growth. The strongest teams optimize toward downstream quality, keep platform claims separate from CRM truth, and build creative around concepts and buyer pain rather than surface metrics. | J8: Audit date | K8: 46088
J9: Version | K9: SaaS v1.0
C12: Section | D12: Weighted score | E12: Max | F12: % of max | G12: Priority note
C13: Revenue Alignment & KPI Logic | D13: ='SaaS Audit Worksheet'!F8 -> 0 | E13: ='SaaS Audit Worksheet'!E8*5 -> 20 | F13: =IFERROR(D13/E13,"") -> 0 | G13: =IF(F13="","",IF(F13<0.6,"Needs attention",IF(F13<0.8,"Solid","Strong"))) -> Needs attention
C14: ICP, Segmentation & Market Focus | D14: ='SaaS Audit Worksheet'!F13 -> 0 | E14: ='SaaS Audit Worksheet'!E13*5 -> 16.5 | F14: =IFERROR(D14/E14,"") -> 0 | G14: =IF(F14="","",IF(F14<0.6,"Needs attention",IF(F14<0.8,"Solid","Strong"))) -> Needs attention
C15: Conversion Signals & Offline Feedback | D15: ='SaaS Audit Worksheet'!F19 -> 0 | E15: ='SaaS Audit Worksheet'!E19*5 -> 25 | F15: =IFERROR(D15/E15,"") -> 0 | G15: =IF(F15="","",IF(F15<0.6,"Needs attention",IF(F15<0.8,"Solid","Strong"))) -> Needs attention
C16: Tracking, Attribution & Source Integrity | D16: ='SaaS Audit Worksheet'!F25 -> 0 | E16: ='SaaS Audit Worksheet'!E25*5 -> 25 | F16: =IFERROR(D16/E16,"") -> 0 | G16: =IF(F16="","",IF(F16<0.6,"Needs attention",IF(F16<0.8,"Solid","Strong"))) -> Needs attention
C17: Full-Funnel Campaign Structure | D17: ='SaaS Audit Worksheet'!F30 -> 0 | E17: ='SaaS Audit Worksheet'!E30*5 -> 16.5 | F17: =IFERROR(D17/E17,"") -> 0 | G17: =IF(F17="","",IF(F17<0.6,"Needs attention",IF(F17<0.8,"Solid","Strong"))) -> Needs attention
C18: Offer, Messaging & Positioning | D18: ='SaaS Audit Worksheet'!F36 -> 0 | E18: ='SaaS Audit Worksheet'!E36*5 -> 24 | F18: =IFERROR(D18/E18,"") -> 0 | G18: =IF(F18="","",IF(F18<0.6,"Needs attention",IF(F18<0.8,"Solid","Strong"))) -> Needs attention
C19: Creative System & Content Diversification | D19: ='SaaS Audit Worksheet'!F42 -> 0 | E19: ='SaaS Audit Worksheet'!E42*5 -> 21 | F19: =IFERROR(D19/E19,"") -> 0 | G19: =IF(F19="","",IF(F19<0.6,"Needs attention",IF(F19<0.8,"Solid","Strong"))) -> Needs attention
C20: Landing Pages & Conversion Path | D20: ='SaaS Audit Worksheet'!F48 -> 0 | E20: ='SaaS Audit Worksheet'!E48*5 -> 21.5 | F20: =IFERROR(D20/E20,"") -> 0 | G20: =IF(F20="","",IF(F20<0.6,"Needs attention",IF(F20<0.8,"Solid","Strong"))) -> Needs attention
C21: Sales Alignment & Lead Quality Loop | D21: ='SaaS Audit Worksheet'!F54 -> 0 | E21: ='SaaS Audit Worksheet'!E54*5 -> 23 | F21: =IFERROR(D21/E21,"") -> 0 | G21: =IF(F21="","",IF(F21<0.6,"Needs attention",IF(F21<0.8,"Solid","Strong"))) -> Needs attention
C22: Testing Discipline & Experimentation | D22: ='SaaS Audit Worksheet'!F59 -> 0 | E22: ='SaaS Audit Worksheet'!E59*5 -> 14 | F22: =IFERROR(D22/E22,"") -> 0 | G22: =IF(F22="","",IF(F22<0.6,"Needs attention",IF(F22<0.8,"Solid","Strong"))) -> Needs attention
C23: Reporting & Decision Quality | D23: ='SaaS Audit Worksheet'!F64 -> 0 | E23: ='SaaS Audit Worksheet'!E64*5 -> 18.5 | F23: =IFERROR(D23/E23,"") -> 0 | G23: =IF(F23="","",IF(F23<0.6,"Needs attention",IF(F23<0.8,"Solid","Strong"))) -> Needs attention
C24: Operational Scalability & Automation | D24: ='SaaS Audit Worksheet'!F69 -> 0 | E24: ='SaaS Audit Worksheet'!E69*5 -> 13.5 | F24: =IFERROR(D24/E24,"") -> 0 | G24: =IF(F24="","",IF(F24<0.6,"Needs attention",IF(F24<0.8,"Solid","Strong"))) -> Needs attention
C27: Priority actions
C28: 1st priority
C29: 2nd priority
C30: 3rd priority

Sheet SaaS Audit Worksheet
A1: B2B SaaS Paid Media Audit Scorecard
A2: Score each audit item from 1 to 5. Use the notes columns to capture evidence and actions. This version is tuned for SaaS / AI SaaS / B2B pipeline generation.
A3: Section | B3: No | C3: Audit Item | D3: Rating (1-5) | E3: Weight | F3: Weighted Score | G3: Evidence / Findings | H3: Recommendation / Next Step | I3: Priority | J3: Owner / Notes
A4: 1. Revenue Alignment & KPI Logic
A5: Revenue Alignment & KPI Logic | B5: 1.1 | C5: Is paid media optimization aligned to pipeline and revenue rather than raw lead volume? | E5: 1.5 | F5: =IFERROR(D5*E5,"") -> 0
A6: Revenue Alignment & KPI Logic | B6: 1.2 | C6: Are stage definitions clear (MQL, SQL, Opportunity, Closed Won) and agreed with Sales? | E6: 1.2 | F6: =IFERROR(D6*E6,"") -> 0
A7: Revenue Alignment & KPI Logic | B7: 1.3 | C7: Are primary steering metrics business-relevant (CAC, pipeline $, SQL rate, win rate, payback) rather than only CPL/CTR? | E7: 1.3 | F7: =IFERROR(D7*E7,"") -> 0
A8: Revenue Alignment & KPI Logic | B8: 1.T | C8: Section subtotal | E8: =SUM(E5:E7) -> 4 | F8: =SUM(F5:F7) -> 0 | G8: =IFERROR(F8/(E8*5),"") -> 0
A9: 2. ICP, Segmentation & Market Focus
A10: ICP, Segmentation & Market Focus | B10: 2.1 | C10: Is there a clearly defined ICP with usable firmographic, technographic, and buying-intent criteria? | E10: 1.2 | F10: =IFERROR(D10*E10,"") -> 0
A11: ICP, Segmentation & Market Focus | B11: 2.2 | C11: Are segments prioritized by revenue potential, fit, and sales velocity? | E11: 1 | F11: =IFERROR(D11*E11,"") -> 0
A12: ICP, Segmentation & Market Focus | B12: 2.3 | C12: Are campaigns and messaging differentiated by segment, use case, or buyer role? | E12: 1.1 | F12: =IFERROR(D12*E12,"") -> 0
A13: ICP, Segmentation & Market Focus | B13: 2.T | C13: Section subtotal | E13: =SUM(E10:E12) -> 3.3 | F13: =SUM(F10:F12) -> 0 | G13: =IFERROR(F13/(E13*5),"") -> 0
A14: 3. Conversion Signals & Offline Feedback
A15: Conversion Signals & Offline Feedback | B15: 3.1 | C15: Is the platform optimizing toward qualified events (demo qualified, SQL, opportunity) rather than just form fills? | E15: 1.5 | F15: =IFERROR(D15*E15,"") -> 0
A16: Conversion Signals & Offline Feedback | B16: 3.2 | C16: Are offline conversions or CRM stages imported back into ad platforms where possible? | E16: 1.4 | F16: =IFERROR(D16*E16,"") -> 0
A17: Conversion Signals & Offline Feedback | B17: 3.3 | C17: Are spam, duplicates, students, partners, and poor-fit leads excluded from the learning signal? | E17: 1 | F17: =IFERROR(D17*E17,"") -> 0
A18: Conversion Signals & Offline Feedback | B18: 3.4 | C18: Is first-party data used to distinguish high-value from low-value outcomes? | E18: 1.1 | F18: =IFERROR(D18*E18,"") -> 0
A19: Conversion Signals & Offline Feedback | B19: 3.T | C19: Section subtotal | E19: =SUM(E15:E18) -> 5 | F19: =SUM(F15:F18) -> 0 | G19: =IFERROR(F19/(E19*5),"") -> 0
A20: 4. Tracking, Attribution & Source Integrity
A21: Tracking, Attribution & Source Integrity | B21: 4.1 | C21: Is tracking trustworthy across website, CRM, and ad platforms? | E21: 1.5 | F21: =IFERROR(D21*E21,"") -> 0
A22: Tracking, Attribution & Source Integrity | B22: 4.2 | C22: Are UTMs, channel mappings, and lead-source rules standardized? | E22: 1 | F22: =IFERROR(D22*E22,"") -> 0
A23: Tracking, Attribution & Source Integrity | B23: 4.3 | C23: Is there a clear primary source of truth outside ad platforms? | E23: 1.3 | F23: =IFERROR(D23*E23,"") -> 0
A24: Tracking, Attribution & Source Integrity | B24: 4.4 | C24: Does the team distinguish attribution from contribution/incrementality? | E24: 1.2 | F24: =IFERROR(D24*E24,"") -> 0
A25: Tracking, Attribution & Source Integrity | B25: 4.T | C25: Section subtotal | E25: =SUM(E21:E24) -> 5 | F25: =SUM(F21:F24) -> 0 | G25: =IFERROR(F25/(E25*5),"") -> 0
A26: 5. Full-Funnel Campaign Structure
A27: Full-Funnel Campaign Structure | B27: 5.1 | C27: Are Awareness, Consideration, and Conversion campaigns mapped to distinct jobs? | E27: 1 | F27: =IFERROR(D27*E27,"") -> 0
A28: Full-Funnel Campaign Structure | B28: 5.2 | C28: Is channel usage appropriate for the stage and buying motion? | E28: 1.1 | F28: =IFERROR(D28*E28,"") -> 0
A29: Full-Funnel Campaign Structure | B29: 5.3 | C29: Are remarketing and demand-capture activities interpreted carefully rather than treated as net-new by default? | E29: 1.2 | F29: =IFERROR(D29*E29,"") -> 0
A30: Full-Funnel Campaign Structure | B30: 5.T | C30: Section subtotal | E30: =SUM(E27:E29) -> 3.3 | F30: =SUM(F27:F29) -> 0 | G30: =IFERROR(F30/(E30*5),"") -> 0
A31: 6. Offer, Messaging & Positioning
A32: Offer, Messaging & Positioning | B32: 6.1 | C32: Is the core category story clear and specific (what it is, who it is for, why it matters now)? | E32: 1.3 | F32: =IFERROR(D32*E32,"") -> 0
A33: Offer, Messaging & Positioning | B33: 6.2 | C33: Are message angles built around buyer pains, outcomes, objections, and proof? | E33: 1.2 | F33: =IFERROR(D33*E33,"") -> 0
A34: Offer, Messaging & Positioning | B34: 6.3 | C34: Are creatives and landing pages adapted by persona, use case, or stage? | E34: 1.1 | F34: =IFERROR(D34*E34,"") -> 0
A35: Offer, Messaging & Positioning | B35: 6.4 | C35: Is AI positioning concrete and differentiated rather than generic AI hype? | E35: 1.2 | F35: =IFERROR(D35*E35,"") -> 0
A36: Offer, Messaging & Positioning | B36: 6.T | C36: Section subtotal | E36: =SUM(E32:E35) -> 4.8 | F36: =SUM(F32:F35) -> 0 | G36: =IFERROR(F36/(E36*5),"") -> 0
A37: 7. Creative System & Content Diversification
A38: Creative System & Content Diversification | B38: 7.1 | C38: Are creatives organized by concept rather than random asset naming? | E38: 1 | F38: =IFERROR(D38*E38,"") -> 0
A39: Creative System & Content Diversification | B39: 7.2 | C39: Is there enough variation across product demo, use case, proof, objection handling, founder/expert, and offer? | E39: 1.2 | F39: =IFERROR(D39*E39,"") -> 0
A40: Creative System & Content Diversification | B40: 7.3 | C40: Are winning concepts iterated with multiple hooks and executions? | E40: 1.1 | F40: =IFERROR(D40*E40,"") -> 0
...
