Workbook

Sheet Hinweise
A1: homie SaaS-Wachstumsmodell — Startarbeitsmappe
A3: Zweck | B3: Annahmenbasiertes SaaS-Modell für homie zur Unterstützung einer Bewerbung als Marketing Manager Paid & Performance.
A5: Verwendung
A6: 1. Prüfen Sie die bekannten Eingaben und ändern Sie öffentliche Faktendaten nur, wenn Sie besser belegte Quellen haben.
A7: 2. Bearbeiten Sie nur blau formatierte Zellen in „Annahmen“ und „homie Eingaben“.
A8: 3. Prüfen Sie die Unit Economics je Tarif.
A9: 4. Bauen Sie Kundenwachstum und Umsatzlogik in der 5-Jahres-Projektion auf.
A10: 5. Stellen Sie die wichtigsten KPIs im Dashboard dar.

Sheet Kennzahlen & Definitionen
A1: Kennzahl | B1: Vollständiger Name | C1: Formel | D1: Warum sie wichtig ist | E1: Warum sie für homie wichtig ist
A2: MRR | B2: Monatlich wiederkehrender Umsatz | C2: Summe der aktiven monatlich wiederkehrenden Abo-Umsätze | D2: Zentrale monatliche Skalierungskennzahl | E2: Nützlich zur Verfolgung des kurzfristigen kommerziellen Momentums
A3: ARR | B3: Jährlich wiederkehrender Umsatz | C3: MRR * 12 | D3: Zentrale SaaS-Bewertungs- und Skalierungskennzahl | E3: Zentral für die Erzählung des Weges zur 1-Mrd.-€-Bewertung
A4: ARR Growth % | B4: Wachstum des jährlich wiederkehrenden Umsatzes | C4: (Ending ARR - Beginning ARR) / Beginning ARR | D4: Zeigt das Wachstumstempo | E4: Erforderlich für Bewertungssensitivität und Rule-of-40-Einordnung
A5: Net New ARR | B5: Netto neu hinzugewonnener jährlich wiederkehrender Umsatz | C5: New ARR + Expansion ARR - Churned ARR - Contraction ARR | D5: Misst echtes inkrementelles Wachstum | E5: Verbindet bezahlte Akquise mit nachhaltigem Wachstum
A6: CPL | B6: Kosten pro Lead | C6: Ad Spend / Leads | D6: Effizienz im oberen Funnel | E6: Die Rolle verweist ausdrücklich auf Lead-Generierungseffizienz
A7: CAC | B7: Kundenakquisitionskosten | C7: Sales & Marketing Spend / New Customers | D7: Akquiseeffizienz | E7: Die Rolle verweist ausdrücklich auf CAC
A8: Pipeline Created | B8: Wert der qualifizierten Pipeline | C8: Wert der geschaffenen qualifizierten Opportunities | D8: Misst Umsatzwirkung über Leads hinaus | E8: Die Rolle betont den Pipeline-Impact
A9: SQL-to-Customer | B9: Sales-Conversion-Rate | C9: Closed Won Customers / SQLs | D9: Misst Lead-Qualität und die Abstimmung mit Sales | E9: Kritisch für die Abstimmung zwischen Paid und Sales
A10: LTV / CLTV | B10: Customer Lifetime Value | C10: Monatlicher Bruttogewinn pro Kunde / monatlicher Churn | D10: Kundenwert über die gesamte Laufzeit | E10: Erforderlich zur Bewertung skalierbarer bezahlter Akquise
A11: CAC Payback | B11: CAC-Amortisationsdauer | C11: CAC / monatlicher Bruttogewinn pro Kunde | D11: Geschwindigkeit der Rückgewinnung des eingesetzten Kapitals | E11: Kritisch für Budgetentscheidungen im Wachstum
A12: LTV:CAC | B12: Verhältnis von Lifetime Value zu CAC | C12: LTV / CAC | D12: Qualität der Unit Economics | E12: Zeigt, ob Wachstum wirtschaftlich tragfähig ist
... A16: Burn Multiple | B16: Burn-Effizienz | C16: Net Burn / Net New ARR | D16: Kapitaleffizienz | E16: Nützlich für investorentaugliches Storytelling

Sheet Bekannte Eingaben
A1: Bekannte Eingaben (öffentlich / vom Nutzer bereitgestellt)
A3: Posten | B3: Wert | C3: Einheiten | D3: Hinweise / Quelle
A4: Basic Preis | B4: 190 | C4: EUR / Monat | D4: Öffentliche Preisseite
A5: Basic enthaltene Nachrichten | B5: 2000 | C5: Nachrichten / Monat | D5: Öffentliche Preisseite
A6: Basic Overage-Preis | B6: 0.08 | C6: EUR / zusätzliche Nachricht | D6: Öffentliche Preisseite
A7: Business Preis | B7: 390 | C7: EUR / Monat | D7: Öffentliche Preisseite
A8: Business enthaltene Nachrichten | B8: 5000 | C8: Nachrichten / Monat | D8: Öffentliche Preisseite
A9: Business Overage-Preis | B9: 0.06 | C9: EUR / zusätzliche Nachricht | D9: Öffentliche Preisseite
A10: Professional Preis | B10: 790 | C10: EUR / Monat | D10: Öffentliche Preisseite
A11: Professional enthaltene Nachrichten | B11: 10000 | C11: Nachrichten / Monat | D11: Öffentliche Preisseite
A12: Professional Overage-Preis | B12: 0.05 | C12: EUR / zusätzliche Nachricht | D12: Öffentliche Preisseite
A13: Enterprise Preis | B13: Individuell | C13: EUR / Monat | D13: Enterprise-Preis nicht öffentlich
A14: Aktuelle Teamgröße | B14: 10 | C14: Mitarbeitende | D14: Nutzerrecherche / Jobkontext

Sheet Annahmen
A1: Annahmen (blaue Zellen bearbeiten)
A3: Kategorie | B3: Annahme | C3: Basisfall | D3: Einheiten | E3: Kommentar
A4: Steuerung | B4: Aktives Enterprise-Szenario | C4: Basis | D4: Text | E4: Auswahl „Konservativ / Basis / Aggressiv“ nur für die Präsentation
A5: Margenannahmen | B5: Basic Bruttomarge | C5: 0.78 | D5: % | E5: Niedriger Tarif; Basisfall für AI-SaaS-Ökonomie
A6: Margenannahmen | B6: Business Bruttomarge | C6: 0.8 | D6: % | E6: Kern-SMB-Tarif
A7: Margenannahmen | B7: Professional Bruttomarge | C7: 0.82 | D7: % | E7: Höherwertiger Tarif mit stärkeren Paketökonomiken
A8: Margenannahmen | B8: Enterprise Bruttomarge | C8: 0.8 | D8: % | E8: Individueller Tarif; potenziell geringere Serviceintensität durch ACV ausgeglichen
A9: Churn-Annahmen | B9: Basic monatlicher Churn | C9: 0.04 | D9: % | E9: Höherer Churn im niedrigeren Tarif erwartet
A10: Churn-Annahmen | B10: Business monatlicher Churn | C10: 0.03 | D10: % | E10: Niedriger als Basic aufgrund besserer Passung
A11: Churn-Annahmen | B11: Professional monatlicher Churn | C11: 0.025 | D11: % | E11: Höherwertiger Tarif
A12: Churn-Annahmen | B12: Enterprise monatlicher Churn | C12: 0.015 | D12: % | E12: Strategische / sales-getriebene Retention
A13: CAC / Payback | B13: Basic CAC-Payback-Ziel | C13: 9 | D13: Monate | E13: SMB-ähnlicher Benchmark
A14: CAC / Payback | B14: Business CAC-Payback-Ziel | C14: 9 | D14: Monate | E14: SMB-ähnlicher Benchmark
A15: CAC / Payback | B15: Professional CAC-Payback-Ziel | C15: 12 | D15: Monate | E15: Höherwertig / sales-unterstützt
A16: CAC / Payback | B16: Enterprise CAC-Payback-Ziel | C16: 12 | D16: Monate | E16: Höherwertig / sales-getrieben
... A38: Valuation assumptions | B38: High ARR Multiple | C38: 12 | D38: x | E38: Sensitivity upside
A40: Annual New Customer Growth Schedule
B41: Tarif | C41: 2026 | D41: 2027 | E41: 2028 | F41: 2029 | G41: 2030
B42: Basic | C42: 0.6 | D42: 0.45 | E42: 0.35 | F42: 0.3 | G42: 0.35
B43: Business | C43: 0.55 | D43: 0.45 | E43: 0.35 | F43: 0.25 | G43: 0.28
B44: Professional | C44: 0.5 | D44: 0.4 | E44: 0.3 | F44: 0.24 | G44: 0.27
B45: Enterprise | C45: 0.35 | D45: 0.3 | E45: 0.25 | F45: 0.22 | G45: 0.24
A48: Annual Expansion Rate on Starting ARR
B49: Tarif | C49: Expansion %
B50: Basic | C50: 0.03
B51: Business | C51: 0.05
B52: Professional | C52: 0.1
B53: Enterprise | C53: 0.14
A56: Current Team Counts
B57: Role | C57: Count
B58: Leadership | C58: 2
B59: Product / AI | C59: 4
B60: Marketing | C60: 2
B61: Sales | C61: 2
B62: Customer Success | C62: 1
A64: Operating Growth Controls
B65: Annual Payroll Growth | C65: 0.1 | D65: % | E65: Applied after first projection year
A68: Annual ARPA Growth Schedule
B69: Tarif | C69: 2026 | D69: 2027 | E69: 2028 | F69: 2029 | G69: 2030
B70: Basic | C70: 0.02 | D70: 0.02 | E70: 0.02 | F70: 0.02 | G70: 0.02
...

Sheet homie Eingaben
A1: homie Eingaben
A2: Zweck | B2: Öffentliche kommerzielle Eingabeschicht zur Verankerung von Preisen, Nutzung, Overages und dem anfänglichen Kundenmix.
A4: Abschnitt A — Preise je Tarif
A5: Tarif | B5: Monatlicher Preis (€) | C5: Jährlicher Basis-ARR (€) | D5: Quelle / Hinweise
A6: Basic | B6: 190 | C6: =B6*12 -> 2280 | D6: https://yourhomie.ai/preise
A7: Business | B7: 390 | C7: =B7*12 -> 4680 | D7: https://yourhomie.ai/preise
A8: Professional | B8: 790 | C8: =B8*12 -> 9480 | D8: https://yourhomie.ai/preise
A9: Enterprise | D9: Custom pricing; annual ACV modeled below
A10: Abschnitt B — enthaltene Nutzung und Overages
A11: Tarif | B11: Enthaltene Nachrichten | C11: Overage-Preis (€) | D11: Quelle / Hinweise
A12: Basic | B12: 2000 | C12: 0.08 | D12: https://yourhomie.ai/preise
A13: Business | B13: 5000 | C13: 0.06 | D13: https://yourhomie.ai/preise
A14: Professional | B14: 10000 | C14: 0.05 | D14: https://yourhomie.ai/preise
A15: Enterprise | B15: Individuell | C15: Individuell | D15: Custom usage / pricing
A16: Abschnitt C — kommerzielle Rolle jedes Tarifs
A17: Tarif | B17: Wahrscheinliche GTM-Rolle | C17: Kommentar
A18: Basic | B18: Niedrigschwelliger Einstieg | C18: Kleinere Händler / von Test zu Paid
A19: Business | B19: Kern-SMB-Tarif | C19: Höhere SMB-Nutzungsabsicht
A20: Professional | B20: Wichtigster Wachstumstarif | C20: Sales-unterstützt / stärkster sichtbarer Wert
A21: Enterprise | B21: Strategische Accounts | C21: Individueller Hebel für Upsell und Expansion
A22: Abschnitt D — Annahmen zum Overage-Uplift
A23: Tarif | B23: Monatlicher Basispreis (€) | C23: Overage-Umsatz-Uplift % | D23: Effektiver monatlicher ARPA (€) | E23: Effektiv annualisierter ARR (€) | F23: Hinweis
A24: Basic | B24: =B6 -> 190 | C24: 0.08 | D24: =B24*(1+C24) -> 205.2 | E24: =D24*12 -> 2462.4 | F24: Platzhalterannahme
A25: Business | B25: =B7 -> 390 | C25: 0.1 | D25: =B25*(1+C25) -> 429 | E25: =D25*12 -> 5148 | F25: Platzhalterannahme
A26: Professional | B26: =B8 -> 790 | C26: 0.12 | D26: =B26*(1+C26) -> 884.8 | E26: =D26*12 -> 10617.6 | F26: Platzhalterannahme
A27: Enterprise | B27: ='homie Eingaben'!C37 -> 3500 | C27: 0.15 | D27: =B27*(1+C27) -> 4025 | E27: =D27*12 -> 48300 | F27: Enterprise-ACV-Abschnitt unten verwenden
A28: Abschnitt E — anfängliche Kundenzahlen (Platzhalter für den Basisfall)
A29: Tarif | B29: Startkunden | C29: Kommentar
A30: Basic | B30: 40 | C30: Nur angenommener Startwert
A31: Business | B31: 30 | C31: Nur angenommener Startwert
A32: Professional | B32: 20 | C32: Nur angenommener Startwert
A33: Enterprise | B33: 5 | C33: Nur angenommener Startwert
A34: Abschnitt F — Enterprise-ACV-Szenarien
A35: Szenario | B35: Enterprise ACV (€ / Jahr) | C35: Monatliches Äquivalent (€) | D35: Hinweis
A36: Konservativ | B36: 30000 | C36: =B36/12 -> 2500 | D36: Scenario input
A37: Basis | B37: 42000 | C37: =B37/12 -> 3500 | D37: Primary base case
A38: Aggressiv | B38: 60000 | C38: =B38/12 -> 5000 | D38: Scenario input
A40: Section G — Modeling notes
A41: • | B41: Basic and Business are treated as acquisition / lower-friction entry layers.
A42: • | B42: Professional is treated as the primary growth and efficiency tier.
...

Sheet Unit Economics
A1: Unit Economics je Tarif
A3: Tarif | B3: Basis-MRR | C3: Overage-Uplift % | D3: Effektive MRR | E3: Bruttomarge % | F3: Monatlicher Bruttogewinn | G3: Monatlicher Churn | H3: Laufzeit (Monate) | I3: LTV | J3: Ziel-CAC-Payback (Monate) | K3: Max. CAC | L3: Illustrativer CAC | M3: LTV:CAC
A4: Basic | B4: ='homie Eingaben'!B24 -> 190 | C4: ='homie Eingaben'!C24 -> 0.08 | D4: =B4*(1+C4) -> 205.2 | E4: =Annahmen!C5 -> 0.78 | F4: =D4*E4 -> 160.056 | G4: =Annahmen!C9 -> 0.04 | H4: =IF(G4>0,1/G4,0) -> 25 | I4: =IF(G4>0,F4/G4,0) -> 4001.4 | J4: =Annahmen!C13 -> 9 | K4: =F4*J4 -> 1440.504 | L4: =K4*Annahmen!C17 -> 1008.3528 | M4: =IF(L4>0,I4/L4,0) -> 3.968254
A5: Business | B5: ='homie Eingaben'!B25 -> 390 | C5: ='homie Eingaben'!C25 -> 0.1 | D5: =B5*(1+C5) -> 429 | E5: =Annahmen!C6 -> 0.8 | F5: =D5*E5 -> 343.2 | G5: =Annahmen!C10 -> 0.03 | H5: =IF(G5>0,1/G5,0) -> 33.333333 | I5: =IF(G5>0,F5/G5,0) -> 11440 | J5: =Annahmen!C14 -> 9 | K5: =F5*J5 -> 3088.8 | L5: =K5*Annahmen!C18 -> 2223.936 | M5: =IF(L5>0,I5/L5,0) -> 5.1440329
A6: Professional | B6: ='homie Eingaben'!B26 -> 790 | C6: ='homie Eingaben'!C26 -> 0.12 | D6: =B6*(1+C6) -> 884.8 | E6: =Annahmen!C7 -> 0.82 | F6: =D6*E6 -> 725.536 | G6: =Annahmen!C11 -> 0.025 | H6: =IF(G6>0,1/G6,0) -> 40 | I6: =IF(G6>0,F6/G6,0) -> 29021.44 | J6: =Annahmen!C15 -> 12 | K6: =F6*J6 -> 8706.432 | L6: =K6*Annahmen!C19 -> 6529.824 | M6: =IF(L6>0,I6/L6,0) -> 4.4444444
A7: Enterprise | B7: ='homie Eingaben'!B27 -> 3500 | C7: ='homie Eingaben'!C27 -> 0.15 | D7: =B7*(1+C7) -> 4025 | E7: =Annahmen!C8 -> 0.8 | F7: =D7*E7 -> 3220 | G7: =Annahmen!C12 -> 0.015 | H7: =IF(G7>0,1/G7,0) -> 66.666667 | I7: =IF(G7>0,F7/G7,0) -> 214666.67 | J7: =Annahmen!C16 -> 12 | K7: =F7*J7 -> 38640 | L7: =K7*Annahmen!C20 -> 27048 | M7: =IF(L7>0,I7/L7,0) -> 7.9365079

Sheet 5-Jahres-Projektion
A1: 5-Jahres-Projektion (Basisfall, jährlich, nach Tarif)
B3: 2026 | C3: 2027 | D3: 2028 | E3: 2029 | F3: 2030 | H3: ARR nach Tarif | I3: 2026 | J3: 2027 | K3: 2028 | L3: 2029 | M3: 2030
A4: Basic Logo-Brücke | H4: Basic | I4: =B9*B34 -> 123070.75 | J4: =C9*C34 -> 133217.81 | K4: =D9*D34 -> 133269.05 | L4: =E9*E34 -> 125272.9 | M4: =F9*F34 -> 125059.67
A5: Start-Logos | B5: ='homie Eingaben'!B30 -> 40 | C5: =B9 -> 49 | D5: =C9 -> 52 | E5: =D9 -> 51 | F5: =E9 -> 47 | H5: Business | I5: =B16*B35 -> 201492.72 | J5: =C16*C35 -> 240306.58 | K5: =D16*D35 -> 261278.79 | L5: =E16*E35 -> 265822.77 | M5: =F16*F35 -> 282599.14
A6: Wachstumsrate | B6: =Annahmen!C42 -> 0.6 | C6: =Annahmen!D42 -> 0.45 | D6: =Annahmen!E42 -> 0.35 | E6: =Annahmen!F42 -> 0.3 | F6: =Annahmen!G42 -> 0.35 | H6: Professional | I6: =B23*B36 -> 278712 | J6: =C23*C36 -> 339471.22 | K6: =D23*D36 -> 384656.01 | L6: =E23*E36 -> 407735.37 | M6: =F23*F36 -> 446141.41
A7: Neue Logos | B7: =ROUND(B5*B6,0) -> 24 | C7: =ROUND(C5*C6,0) -> 22 | D7: =ROUND(D5*D6,0) -> 18 | E7: =ROUND(E5*E6,0) -> 15 | F7: =ROUND(F5*F6,0) -> 16 | H7: Enterprise | I7: =B30*B37 -> 307188 | J7: =C30*C37 -> 383473.02 | K7: =D30*D37 -> 473315.27 | L7: =E30*E37 -> 575078.05 | M7: =F30*F37 -> 690093.66
A8: Abgewanderte Logos | B8: =ROUND(B5*B38,0) -> 15 | C8: =ROUND(C5*C38,0) -> 19 | D8: =ROUND(D5*D38,0) -> 19 | E8: =ROUND(E5*E38,0) -> 19 | F8: =ROUND(F5*F38,0) -> 17 | H8: Total ARR | I8: =SUM(I4:I7) -> 910463.47 | J8: =SUM(J4:J7) -> 1096468.6 | K8: =SUM(K4:K7) -> 1252519.1 | L8: =SUM(L4:L7) -> 1373909.1 | M8: =SUM(M4:M7) -> 1543893.9
A9: End-Logos | B9: =B5+B7-B8 -> 49 | C9: =C5+C7-C8 -> 52 | D9: =D5+D7-D8 -> 51 | E9: =E5+E7-E8 -> 47 | F9: =F5+F7-F8 -> 46
A11: Business Logo-Brücke | H11: ARR-Mix nach Tarif | I11: 2026 | J11: 2027 | K11: 2028 | L11: 2029 | M11: 2030
A12: Start-Logos | B12: ='homie Eingaben'!B31 -> 30 | C12: =B16 -> 38 | D12: =C16 -> 44 | E12: =D16 -> 46 | F12: =E16 -> 45 | H12: Basic % | I12: =IF(I8>0,I4/I8,0) -> 0.13517374 | J12: =IF(J8>0,J4/J8,0) -> 0.12149715 | K12: =IF(K8>0,K4/K8,0) -> 0.10640081 | L12: =IF(L8>0,L4/L8,0) -> 0.091179908 | M12: =IF(M8>0,M4/M8,0) -> 0.081002765
A13: Wachstumsrate | B13: =Annahmen!C43 -> 0.55 | C13: =Annahmen!D43 -> 0.45 | D13: =Annahmen!E43 -> 0.35 | E13: =Annahmen!F43 -> 0.25 | F13: =Annahmen!G43 -> 0.28 | H13: Business % | I13: =IF(I8>0,I5/I8,0) -> 0.22130786 | J13: =IF(J8>0,J5/J8,0) -> 0.21916412 | K13: =IF(K8>0,K5/K8,0) -> 0.20860264 | L13: =IF(L8>0,L5/L8,0) -> 0.19347915 | M13: =IF(M8>0,M5/M8,0) -> 0.18304311
A14: Neue Logos | B14: =ROUND(B12*B13,0) -> 17 | C14: =ROUND(C12*C13,0) -> 17 | D14: =ROUND(D12*D13,0) -> 15 | E14: =ROUND(E12*E13,0) -> 12 | F14: =ROUND(F12*F13,0) -> 13 | H14: Professional % | I14: =IF(I8>0,I6/I8,0) -> 0.30612101 | J14: =IF(J8>0,J6/J8,0) -> 0.30960413 | K14: =IF(K8>0,K6/K8,0) -> 0.3071059 | L14: =IF(L8>0,L6/L8,0) -> 0.29677026 | M14: =IF(M8>0,M6/M8,0) -> 0.28897155
A15: Abgewanderte Logos | B15: =ROUND(B12*B39,0) -> 9 | C15: =ROUND(C12*C39,0) -> 11 | D15: =ROUND(D12*D39,0) -> 13 | E15: =ROUND(E12*E39,0) -> 13 | F15: =ROUND(F12*F39,0) -> 12 | H15: Enterprise % | I15: =IF(I8>0,I7/I8,0) -> 0.33739739 | J15: =IF(J8>0,J7/J8,0) -> 0.3497346 | K15: =IF(K8>0,K7/K8,0) -> 0.37789066 | L15: =IF(L8>0,L7/L8,0) -> 0.41857067 | M15: =IF(M8>0,M7/M8,0) -> 0.44698257
A16: End-Logos | B16: =B12+B14-B15 -> 38 | C16: =C12+C14-C15 -> 44 | D16: =D12+D14-D15 -> 46 | E16: =E12+E14-E15 -> 45 | F16: =F12+F14-F15 -> 46 | H16: Gesamt | I16: =SUM(I12:I15) -> 1 | J16: =SUM(J12:J15) -> 1 | K16: =SUM(K12:K15) -> 1 | L16: =SUM(L12:L15) -> 1 | M16: =SUM(M12:M15) -> 1
A18: Professional Logo-Brücke
A19: Start-Logos | B19: ='homie Eingaben'!B32 -> 20 | C19: =B23 -> 25 | D19: =C23 -> 29 | E19: =D23 -> 31 | F19: =E23 -> 31
A20: Wachstumsrate | B20: =Annahmen!C44 -> 0.5 | C20: =Annahmen!D44 -> 0.4 | D20: =Annahmen!E44 -> 0.3 | E20: =Annahmen!F44 -> 0.24 | F20: =Annahmen!G44 -> 0.27
A21: Neue Logos | B21: =ROUND(B19*B20,0) -> 10 | C21: =ROUND(C19*C20,0) -> 10 | D21: =ROUND(D19*D20,0) -> 9 | E21: =ROUND(E19*E20,0) -> 7 | F21: =ROUND(F19*F20,0) -> 8
A22: Abgewanderte Logos | B22: =ROUND(B19*B40,0) -> 5 | C22: =ROUND(C19*C40,0) -> 6 | D22: =ROUND(D19*D40,0) -> 7 | E22: =ROUND(E19*E40,0) -> 7 | F22: =ROUND(F19*F40,0) -> 7
A23: End-Logos | B23: =B19+B21-B22 -> 25 | C23: =C19+C21-C22 -> 29 | D23: =D19+D21-D22 -> 31 | E23: =E19+E21-E22 -> 31 | F23: =F19+F21-F22 -> 32
A25: Enterprise Logo-Brücke
A26: Start-Logos | B26: ='homie Eingaben'!B33 -> 5 | C26: =B30 -> 6 | D26: =C30 -> 7 | E26: =D30 -> 8 | F26: =E30 -> 9
A27: Wachstumsrate | B27: =Annahmen!C45 -> 0.35 | C27: =Annahmen!D45 -> 0.3 | D27: =Annahmen!E45 -> 0.25 | E27: =Annahmen!F45 -> 0.22 | F27: =Annahmen!G45 -> 0.24
A28: Neue Logos | B28: =ROUND(B26*B27,0) -> 2 | C28: =ROUND(C26*C27,0) -> 2 | D28: =ROUND(D26*D27,0) -> 2 | E28: =ROUND(E26*E27,0) -> 2 | F28: =ROUND(F26*F27,0) -> 2
A29: Abgewanderte Logos | B29: =ROUND(B26*B41,0) -> 1 | C29: =ROUND(C26*C41,0) -> 1 | D29: =ROUND(D26*D41,0) -> 1 | E29: =ROUND(E26*E41,0) -> 1 | F29: =ROUND(F26*F41,0) -> 1
A30: End-Logos | B30: =B26+B28-B29 -> 6 | C30: =C26+C28-C29 -> 7 | D30: =D26+D28-D29 -> 8 | E30: =E26+E28-E29 -> 9 | F30: =F26+F28-F29 -> 10
A32: Reifegrad-Hilfsschema
B33: 2026 | C33: 2027 | D33: 2028 | E33: 2029 | F33: 2030
A34: ARR / Logo - Basic | B34: ='homie Eingaben'!E24*(1+Annahmen!C70) -> 2511.648 | C34: =B34*(1+Annahmen!D70) -> 2561.881 | D34: =C34*(1+Annahmen!E70) -> 2613.1186 | E34: =D34*(1+Annahmen!F70) -> 2665.381 | F34: =E34*(1+Annahmen!G70) -> 2718.6886
A35: ARR / Logo - Business | B35: ='homie Eingaben'!E25*(1+Annahmen!C71) -> 5302.44 | C35: =B35*(1+Annahmen!D71) -> 5461.5132 | D35: =C35*(1+Annahmen!E71) -> 5679.9737 | E35: =D35*(1+Annahmen!F71) -> 5907.1727 | F35: =E35*(1+Annahmen!G71) -> 6143.4596
A36: ARR / Logo - Professional | B36: ='homie Eingaben'!E26*(1+Annahmen!C72) -> 11148.48 | C36: =B36*(1+Annahmen!D72) -> 11705.904 | D36: =C36*(1+Annahmen!E72) -> 12408.258 | E36: =D36*(1+Annahmen!F72) -> 13152.754 | F36: =E36*(1+Annahmen!G72) -> 13941.919
A37: ARR / Logo - Enterprise | B37: ='homie Eingaben'!E27*(1+Annahmen!C73) -> 51198 | C37: =B37*(1+Annahmen!D73) -> 54781.86 | D37: =C37*(1+Annahmen!E73) -> 59164.409 | E37: =D37*(1+Annahmen!F73) -> 63897.562 | F37: =E37*(1+Annahmen!G73) -> 69009.366
A38: Jährlicher Churn - Basic | B38: =1-(1-('Unit Economics'!G4*Annahmen!C78))^12 -> 0.38729024 | C38: =1-(1-('Unit Economics'!G4*Annahmen!D78))^12 -> 0.38113498 | D38: =1-(1-('Unit Economics'!G4*Annahmen!E78))^12 -> 0.37492309 | E38: =1-(1-('Unit Economics'!G4*Annahmen!F78))^12 -> 0.37179576 | F38: =1-(1-('Unit Economics'!G4*Annahmen!G78))^12 -> 0.37179576
A39: Jährlicher Churn - Business | B39: =1-(1-('Unit Economics'!G5*Annahmen!C79))^12 -> 0.30615764 | C39: =1-(1-('Unit Economics'!G5*Annahmen!D79))^12 -> 0.29578692 | D39: =1-(1-('Unit Economics'!G5*Annahmen!E79))^12 -> 0.28791585 | E39: =1-(1-('Unit Economics'!G5*Annahmen!F79))^12 -> 0.27996421 | F39: =1-(1-('Unit Economics'!G5*Annahmen!G79))^12 -> 0.27461799
A40: Jährlicher Churn - Professional | B40: =1-(1-('Unit Economics'!G6*Annahmen!C80))^12 -> 0.26200165 | C40: =1-(1-('Unit Economics'!G6*Annahmen!D80))^12 -> 0.25056743 | D40: =1-(1-('Unit Economics'!G6*Annahmen!E80))^12 -> 0.24130338 | E40: =1-(1-('Unit Economics'!G6*Annahmen!F80))^12 -> 0.23428658 | F40: =1-(1-('Unit Economics'!G6*Annahmen!G80))^12 -> 0.22721034
A41: Jährlicher Churn - Enterprise | B41: =1-(1-('Unit Economics'!G7*Annahmen!C81))^12 -> 0.16586803 | C41: =1-(1-('Unit Economics'!G7*Annahmen!D81))^12 -> 0.16128362 | D41: =1-(1-('Unit Economics'!G7*Annahmen!E81))^12 -> 0.15821452 | E41: =1-(1-('Unit Economics'!G7*Annahmen!F81))^12 -> 0.15513514 | F41: =1-(1-('Unit Economics'!G7*Annahmen!G81))^12 -> 0.15049669
A43: ARR-Zusammenfassung
A44: Start-ARR | B44: =B5*B34+B12*B35+B19*B36+B26*B37 -> 738498.72 | C44: =C5*C34+C12*C35+C19*C36+C26*C37 -> 954408.43 | D44: =D5*D34+D12*D35+D19*D36+D26*D37 -> 1159791.4 | E44: =E5*E34+E12*E35+E19*E36+E26*E37 -> 1326580.2 | F44: =F5*F34+F12*F35+F19*F36+F26*F37 -> 1457517.8
A45: Neuer ARR | B45: =B7*B34+B14*B35+B21*B36+B28*B37 -> 364301.83 | C45: =C7*C34+C14*C35+C21*C36+C28*C37 -> 375829.87 | D45: =D7*D34+D14*D35+D21*D36+D28*D37 -> 362238.88 | E45: =E7*E34+E14*E35+E21*E36+E28*E37 -> 330731.19 | F45: =F7*F34+F14*F35+F21*F36+F28*F37 -> 372918.08
A46: Expansion-ARR | B46: =(B5*B34)*(Annahmen!C50+Annahmen!C94)+(B12*B35)*(Annahmen!C51+Annahmen!C95)+(B19*B36)*(Annahmen!C52+Annahmen!C96)+(B26*B37)*(Annahmen!C53+Annahmen!C97) -> 95007.605 | C46: =(C5*C34)*(Annahmen!C50+Annahmen!D94)+(C12*C35)*(Annahmen!C51+Annahmen!D95)+(C19*C36)*(Annahmen!C52+Annahmen!D96)+(C26*C37)*(Annahmen!C53+Annahmen!D97) -> 126257.81 | D46: =(D5*D34)*(Annahmen!C50+Annahmen!E94)+(D12*D35)*(Annahmen!C51+Annahmen!E95)+(D19*D36)*(Annahmen!C52+Annahmen!E96)+(D26*D37)*(Annahmen!C53+Annahmen!E97) -> 159735.7 | E46: =(E5*E34)*(Annahmen!C50+Annahmen!F94)+(E12*E35)*(Annahmen!C51+Annahmen!F95)+(E19*E36)*(Annahmen!C52+Annahmen!F96)+(E26*E37)*(Annahmen!C53+Annahmen!F97) -> 194325.33 | F46: =(F5*F34)*(Annahmen!C50+Annahmen!G94)+(F12*F35)*(Annahmen!C51+Annahmen!G95)+(F19*F36)*(Annahmen!C52+Annahmen!G96)+(F26*F37)*(Annahmen!C53+Annahmen!G97) -> 231635.77
...

Sheet Dashboard
A1: homie Wachstumsmodell-Dashboard | R1: ='5-Jahres-Projektion'!B3 -> 2026 | S1: ='5-Jahres-Projektion'!C3 -> 2027 | T1: ='5-Jahres-Projektion'!D3 -> 2028 | U1: ='5-Jahres-Projektion'!E3 -> 2029 | V1: ='5-Jahres-Projektion'!F3 -> 2030
A2: SaaS-Wachstumsmodell im Basisfall, aufgebaut auf öffentlichen Preisen, transparenten Annahmen, Reifegradlogik und leichter Kapazitätsplanung | R2: ='5-Jahres-Projektion'!B49 -> 1009318.2 | S2: ='5-Jahres-Projektion'!C49 -> 1220924.1 | T2: ='5-Jahres-Projektion'!D49 -> 1406509.8 | U2: ='5-Jahres-Projektion'!E49 -> 1550193.3 | V2: ='5-Jahres-Projektion'!F49 -> 1746973.2
A4: ARR (2030) | C4: ARR-Wachstum % (2030) | E4: Net New ARR (2030) | G4: Bruttomarge % (2030) | I4: Burn Multiple (2030) | K4: Bewertungssensitivität (2030)
A5: ='5-Jahres-Projektion'!F49 -> 1746973.2 | C5: ='5-Jahres-Projektion'!F50 -> 0.12693897 | E5: ='5-Jahres-Projektion'!F48 -> 289455.37 | G5: ='5-Jahres-Projektion'!F51 -> 0.80441685 | I5: =IF('5-Jahres-Projektion'!F48>0,'5-Jahres-Projektion'!F62/'5-Jahres-Projektion'!F48,0) -> 1.9258177 | K5: =TEXT('5-Jahres-Projektion'!F63,"€#,##0")&" – "&TEXT('5-Jahres-Projektion'!F65,"€#,##0") -> €13,975,786 – €20,963,678 | M5: 10x ARR | O5: 12x ARR | R5: Basic | S5: ='5-Jahres-Projektion'!M4 -> 125059.67
M6: ='5-Jahres-Projektion'!F64 -> 17469732 | O6: ='5-Jahres-Projektion'!F65 -> 20963678 | R6: Business | S6: ='5-Jahres-Projektion'!M5 -> 282599.14
A7: Jährlicher wiederkehrender Umsatz im Basisfall | C7: Jährliches Wachstum des wiederkehrenden Umsatzes | E7: Neuer ARR nach Churn-Belastung | G7: Umsatz nach Leistungserbringungskosten | I7: Net Burn ÷ Net New ARR | K7: Sensitivitätsspanne von 8x–12x ARR | R7: Professional | S7: ='5-Jahres-Projektion'!M6 -> 446141.41
R8: Enterprise | S8: ='5-Jahres-Projektion'!M7 -> 690093.66
A9: Wachstumstreiber
A10: ARR nach Jahr | E10: ARR nach Tarif (2030) | H10: Wachstumstreiber (2030) | R10: Neuer Logo-ARR | S10: ='5-Jahres-Projektion'!F45 -> 372918.08
A11: ='5-Jahres-Projektion'!B3 -> 2026 | B11: ='5-Jahres-Projektion'!B49 -> 1009318.2 | E11: Basic | F11: ='5-Jahres-Projektion'!M4 -> 125059.67 | H11: Neuer Logo-ARR | I11: ='5-Jahres-Projektion'!F45 -> 372918.08 | R11: Expansion-ARR | S11: ='5-Jahres-Projektion'!F46 -> 231635.77
A12: ='5-Jahres-Projektion'!C3 -> 2027 | B12: ='5-Jahres-Projektion'!C49 -> 1220924.1 | E12: Business | F12: ='5-Jahres-Projektion'!M5 -> 282599.14 | H12: Expansion-ARR | I12: ='5-Jahres-Projektion'!F46 -> 231635.77 | R12: Verlorener ARR | S12: ='5-Jahres-Projektion'!F47 -> 315098.48
A13: ='5-Jahres-Projektion'!D3 -> 2028 | B13: ='5-Jahres-Projektion'!D49 -> 1406509.8 | E13: Professional | F13: ='5-Jahres-Projektion'!M6 -> 446141.41 | H13: Verlorener ARR | I13: ='5-Jahres-Projektion'!F47 -> 315098.48
A14: ='5-Jahres-Projektion'!E3 -> 2029 | B14: ='5-Jahres-Projektion'!E49 -> 1550193.3 | E14: Enterprise | F14: ='5-Jahres-Projektion'!M7 -> 690093.66 | R14: ='5-Jahres-Projektion'!B3 -> 2026 | S14: ='5-Jahres-Projektion'!C3 -> 2027 | T14: ='5-Jahres-Projektion'!D3 -> 2028 | U14: ='5-Jahres-Projektion'!E3 -> 2029 | V14: ='5-Jahres-Projektion'!F3 -> 2030
A15: ='5-Jahres-Projektion'!F3 -> 2030 | B15: ='5-Jahres-Projektion'!F49 -> 1746973.2 | R15: =IF('5-Jahres-Projektion'!B48>0,'5-Jahres-Projektion'!B62/'5-Jahres-Projektion'!B48,0) -> 2.2188678 | S15: =IF('5-Jahres-Projektion'!C48>0,'5-Jahres-Projektion'!C62/'5-Jahres-Projektion'!C48,0) -> 2.0487885 | T15: =IF('5-Jahres-Projektion'!D48>0,'5-Jahres-Projektion'!D62/'5-Jahres-Projektion'!D48,0) -> 2.1008548 | U15: =IF('5-Jahres-Projektion'!E48>0,'5-Jahres-Projektion'!E62/'5-Jahres-Projektion'!E48,0) -> 2.3990755 | V15: =IF('5-Jahres-Projektion'!F48>0,'5-Jahres-Projektion'!F62/'5-Jahres-Projektion'!F48,0) -> 1.9258177
A17: Der Wachstumstreiber zeigt, wie ARR durch Neukundengewinnung, Expansion und Churn wächst. Professional und Enterprise treiben im Basisfall den größten Teil der Wertdichte. | R17: ='5-Jahres-Projektion'!B3 -> 2026 | S17: ='5-Jahres-Projektion'!C3 -> 2027 | T17: ='5-Jahres-Projektion'!D3 -> 2028 | U17: ='5-Jahres-Projektion'!E3 -> 2029 | V17: ='5-Jahres-Projektion'!F3 -> 2030
R18: ='5-Jahres-Projektion'!B56 -> 3 | S18: ='5-Jahres-Projektion'!C56 -> 3 | T18: ='5-Jahres-Projektion'!D56 -> 3 | U18: ='5-Jahres-Projektion'!E56 -> 3 | V18: ='5-Jahres-Projektion'!F56 -> 3
R19: ='5-Jahres-Projektion'!B58 -> 1 | S19: ='5-Jahres-Projektion'!C58 -> 1 | T19: ='5-Jahres-Projektion'!D58 -> 1 | U19: ='5-Jahres-Projektion'!E58 -> 1 | V19: ='5-Jahres-Projektion'!F58 -> 1
A21: Was treibt das Wachstum?
A22: • Professional ist im Basisfall der wichtigste Wachstumstarif. • Enterprise erhöht Umsatzdichte und Bewertungspotenzial. • Niedrigere Tarife verbreitern die Akquise, haben aber schwächere Retention-Ökonomiken.
A26: Unit Economics je Tarif
A27: Tarif | B27: Effektive MRR | C27: Bruttomarge % | D27: Monatlicher Churn | E27: LTV | F27: Max. CAC | G27: Illustrativer CAC | H27: LTV:CAC | I27: Payback Months | J27: Interpretation
A28: ='Unit Economics'!A4 -> Basic | B28: ='Unit Economics'!D4 -> 205.2 | C28: ='Unit Economics'!E4 -> 0.78 | D28: ='Unit Economics'!G4 -> 0.04 | E28: ='Unit Economics'!I4 -> 4001.4 | F28: ='Unit Economics'!K4 -> 1440.504 | G28: ='Unit Economics'!L4 -> 1008.3528 | H28: ='Unit Economics'!M4 -> 3.968254 | I28: ='Unit Economics'!J4 -> 9 | J28: Professional scheint die beste Balance aus Skalierung, Payback und Retention zu bieten. Enterprise ist strategisch am wertvollsten, erfordert aber vermutlich mehr Sales- und Onboarding-Unterstützung.
A29: ='Unit Economics'!A5 -> Business | B29: ='Unit Economics'!D5 -> 429 | C29: ='Unit Economics'!E5 -> 0.8 | D29: ='Unit Economics'!G5 -> 0.03 | E29: ='Unit Economics'!I5 -> 11440 | F29: ='Unit Economics'!K5 -> 3088.8 | G29: ='Unit Economics'!L5 -> 2223.936 | H29: ='Unit Economics'!M5 -> 5.1440329 | I29: ='Unit Economics'!J5 -> 9
A30: ='Unit Economics'!A6 -> Professional | B30: ='Unit Economics'!D6 -> 884.8 | C30: ='Unit Economics'!E6 -> 0.82 | D30: ='Unit Economics'!G6 -> 0.025 | E30: ='Unit Economics'!I6 -> 29021.44 | F30: ='Unit Economics'!K6 -> 8706.432 | G30: ='Unit Economics'!L6 -> 6529.824 | H30: ='Unit Economics'!M6 -> 4.4444444 | I30: ='Unit Economics'!J6 -> 12
A31: ='Unit Economics'!A7 -> Enterprise | B31: ='Unit Economics'!D7 -> 4025 | C31: ='Unit Economics'!E7 -> 0.8 | D31: ='Unit Economics'!G7 -> 0.015 | E31: ='Unit Economics'!I7 -> 214666.67 | F31: ='Unit Economics'!K7 -> 38640 | G31: ='Unit Economics'!L7 -> 27048 | H31: ='Unit Economics'!M7 -> 7.9365079 | I31: ='Unit Economics'!J7 -> 12
A34: Retention und Expansion
A35: Brutto-ARR-Churn (2030) | E35: NDR / NRR (2030)
A36: =IF('5-Jahres-Projektion'!F44>0,'5-Jahres-Projektion'!F47/'5-Jahres-Projektion'!F44,0) -> 0.21618842 | E36: =IF('5-Jahres-Projektion'!F44>0,('5-Jahres-Projektion'!F44-'5-Jahres-Projektion'!F47+'5-Jahres-Projektion'!F46)/'5-Jahres-Projektion'!F44,0) -> 0.94273641
A38: Umsatzleckage vor Expansion | E38: Nach Expansion gehaltener Umsatz
A39: Retention-Qualität zählt
A40: • Hohes Wachstum ohne Retention wird teuer. • Nutzungsbasierte Expansion und Upgrades verbessern die langfristige ARR-Qualität. • Post-Sales-Erfolg ist daher in AI-SaaS nicht optional.
A46: Kapazitäts-Realitätscheck
A47: Erforderliche Sales-Reps (2030) | E47: Erforderliche CS-Manager (2030) | I47: Kapazitätsbereinigte Personalkosten (2030) | M47: Kapazitätsindikator (2030)
A48: ='5-Jahres-Projektion'!F56 -> 3 | E48: ='5-Jahres-Projektion'!F58 -> 1 | I48: ='5-Jahres-Projektion'!F59 -> 1544625.5 | M48: =IF(OR('5-Jahres-Projektion'!F56>Annahmen!$C$61,'5-Jahres-Projektion'!F58>Annahmen!$C$62),"INADEQUATE","ADEQUATE") -> INADEQUATE
A50: Kapazität zur Unterstützung sales-berührter Nachfrage | E50: Kapazität zur Unterstützung der aktiven Kundenbasis | I50: Personalkosten nach Sales-/CS-Kapazitätsbedarf | M50: Vergleicht den erforderlichen Sales-/CS-Bedarf mit dem aktuellen Team-Baseline
J51: Kapazitätsgrenze
J52: • Paid Acquisition kann nicht unabhängig von Sales-Durchsatz und Customer-Success-Kapazität skalieren. • Das ist besonders relevant für die aktuelle Teamgröße von homie.
A58: Kapitaleffizienz
A59: Sales- & Marketing-Ausgaben (2030) | E59: Net Burn (2030) | I59: Burn Multiple (2030) | M59: Effizienz-Hinweis
A60: ='5-Jahres-Projektion'!F53 -> 154569.44 | E60: ='5-Jahres-Projektion'!F62 -> 557438.27 | I60: =IF('5-Jahres-Projektion'!F48>0,'5-Jahres-Projektion'!F62/'5-Jahres-Projektion'!F48,0) -> 1.9258177 | M60: Die Burn Multiple verbessert sich, wenn ARR schneller wächst als die operativen Kosten. Frühe Effizienzgewinne werden durch CAC-Reife und steigenden Kundenwert getrieben.
...
